Workbook

Sheet Sheet1
A1: Регион | B1: Год | C1: Прибыло | D1: Выбыло | E1: Миграционное сальдо | F1: Тип | G1: Численность постоянного населения на 1 января | H1: Ожидаемая продолжительность жизни при рождении | I1: Суммарный коэффициент рождаемости (всего) | J1: Суммарный коэффициент рождаемости вторых детей | K1: Суммарный коэффициент рождаемости третьих и последующих детей | L1: Суммарный коэффициент рождаемости первых детей | M1: Доля городского населения в общей численности населения на 1 января | N1: Уровень безработицы (по методологии МОТ) | O1: Денежные расходы домашних хозяйств | P1: Натуральный доход домашних хозяйств | Q1: Располагаемые ресурсы домашних хозяйств | R1: Сумма сделанных сбережений домашних хозяйств | S1: Реальная начисленная заработная плата, % к предыдущему году | T1: Структура денежных доходов: Доходы от предпринимательской деятельности | U1: Структура денежных доходов: Доходы от собственности | V1: Структура денежных доходов: Другие доходы | W1: Структура денежных доходов: Оплата труда | X1: Структура денежных доходов: Социальные трансферты | Y1: Структура расходов: Оплата услуг | Z1: Структура расходов: Покупка алкогольных напитков | AA1: Структура расходов: Покупка непродовольственных товаров | AB1: Структура расходов: Покупка продуктов питания | AC1: Структура расходов: Стоимость услуг, оказанных работодателем бесплатно или по льготным ценам | AD1: Уровень бедности, % | AE1: Доля населения с доходами ниже ПМ, % | AF1: Введено в действие жилой площади, тыс. кв. м | AG1: Доля домохозяйств с широкополосным доступом к Интернету, % | AH1: Общая площадь жилых помещений на 1 жителя, кв. м | AI1: Число семей, нуждающихся в жилом помещении, тыс. | AJ1: Сведения о задолженности по кредитам: Жилищные кредиты | AK1: Сведения о задолженности по кредитам: Ипотечные жилищные кредиты | AL1: Сведения о задолженности по кредитам: По кредитам всего | AM1: Сведения о задолженности по кредитам: в том числе: просроченная задолженность по ипотечным кредитам | AN1: ВРП на душу населения, руб. | AO1: Индекс физического объема ВРП на душу населения, % | AP1: Индекс физического объема оборота розничной торговли, % | AQ1: Индекс физического объема платных услуг населению, % | AR1: Индекс изменения стоимости фиксированного набора, % | AS1: Индекс потребительских цен (декабрь к декабрю), % | AT1: Индекс цен на первичном рынке жилья, % | AU1: Стоимость фиксированного набора потребительских товаров и услуг, ₽ | AV1: Валовой коэффициент охвата дошкольным образованием, % | AW1: Обеспеченность местами в ДОУ (на 1000 детей) | AX1: Мощность амбулаторно-поликлинических организаций, посещений в смену | AY1: Обеспеченность больничными койками (на 10 тыс. населения) | AZ1: Численность инвалидов, тыс. человек | BA1: Численность врачей, чел. | BB1: Число больничных коек, ед. | BC1: Число посещений врачей, всего | BD1: Число абортов, всего | BE1: Число зарегистрированных заболеваний: COVID-19 | BF1: Число зарегистрированных заболеваний: Болезни глаза и придаточного аппарата | BG1: Число зарегистрированных заболеваний: Болезни кожи и подкожной клетчатки | BH1: Число зарегистрированных заболеваний: Болезни костно-мышечной системы и соединительной ткани | BI1: Число зарегистрированных заболеваний: Болезни крови и кроветворных органов | BJ1: Число зарегистрированных заболеваний: Болезни мочеполовой системы | BK1: Число зарегистрированных заболеваний: Болезни нервной системы | BL1: Число зарегистрированных заболеваний: Болезни органов дыхания | BM1: Число зарегистрированных заболеваний: Болезни органов пищеварения | BN1: Число зарегистрированных заболеваний: Болезни системы кровообращения | BO1: Число зарегистрированных заболеваний: Болезни уха и сосцевидного отростка | BP1: Число зарегистрированных заболеваний: Болезни эндокринной системы, расстройства питания, нарушения обмена веществ и иммунитета | BQ1: Число зарегистрированных заболеваний: Всего заболеваний | BR1: Число зарегистрированных заболеваний: Некоторые инфекционные и паразитарные болезни | BS1: Число зарегистрированных заболеваний: Новообразования | BT1: Число зарегистрированных заболеваний: Осложнения беременности, родов и послеродового периода | BU1: Число зарегистрированных заболеваний: Психические расстройства и расстройства поведения | BV1: Число зарегистрированных заболеваний: Симптомы, признаки и отклонения от нормы, выявленные при клинических и лабораторных исследованиях, не классифицированные в других рубриках | BW1: Число зарегистрированных заболеваний: Состояния, возникающие в перинатальном периоде | BX1: Плотность населения на 1 января
A2: Алтайский край | B2: 1990 | F2: Субъект РФ | G2: 2640419 | H2: 68.9 | I2: 1.905 | M2: 58.07 | AF2: 1252.1 | BX2: =G2/(VLOOKUP(A2,плотность!A:B,2,0)*1000) -> 3.4078717
A3: Амурская область | B3: 1990 | F3: Субъект РФ | G3: 1055337 | H3: 67.8 | I3: 2.178 | M3: 68.37 | AF3: 579.5 | BX3: =G3/(VLOOKUP(A3,плотность!A:B,2,0)*1000) -> 29.072645
A4: Архангельская область | B4: 1990 | F4: Субъект РФ (агрегированный) | G4: 1575502 | H4: 69.1 | I4: 1.996 | M4: 73.63 | AF4: 663.3 | BX4: =G4/(VLOOKUP(A4,плотность!A:B,2,0)*1000) -> 2.6707951
A5: Архангельская область (без АО) | B5: 1990 | F5: Субъект РФ | AF5: 640.3 | BX5: =G5/(VLOOKUP(A5,плотность!A:B,2,0)*1000) -> 0
A6: Астраханская область | B6: 1990 | F6: Субъект РФ | G6: 997516 | H6: 69.6 | I6: 2.135 | M6: 68.01 | AF6: 403.2 | BX6: =G6/(VLOOKUP(A6,плотность!A:B,2,0)*1000) -> 20.357469
A7: Белгородская область | B7: 1990 | F7: Субъект РФ | G7: 1387455 | H7: 70.2 | I7: 1.905 | M7: 63.26 | AF7: 717.5 | BX7: =G7/(VLOOKUP(A7,плотность!A:B,2,0)*1000) -> 51.197601
A8: Брянская область | B8: 1990 | F8: Субъект РФ | G8: 1470953 | H8: 69.6 | I8: 2.02 | M8: 67.49 | AF8: 633.1 | BX8: =G8/(VLOOKUP(A8,плотность!A:B,2,0)*1000) -> 42.14765
A9: Владимирская область | B9: 1990 | F9: Субъект РФ | G9: 1657068 | H9: 69.5 | I9: 1.787 | M9: 79.31 | AF9: 628.9 | BX9: =G9/(VLOOKUP(A9,плотность!A:B,2,0)*1000) -> 56.943918
A10: Волгоградская область | B10: 1990 | F10: Субъект РФ | G10: 2620147 | H10: 70.4 | I10: 1.91 | M10: 75.76 | AF10: 925.3 | BX10: =G10/(VLOOKUP(A10,плотность!A:B,2,0)*1000) -> 23.207679
A11: Вологодская область | B11: 1990 | F11: Субъект РФ | G11: 1354471 | H11: 69.3 | I11: 2.018 | M11: 65.48 | AF11: 710.7 | BX11: =G11/(VLOOKUP(A11,плотность!A:B,2,0)*1000) -> 9.3735017
A12: Воронежская область | B12: 1990 | F12: Субъект РФ | G12: 2471569 | H12: 70.4 | I12: 1.776 | M12: 60.94 | AF12: 939.7 | BX12: =G12/(VLOOKUP(A12,плотность!A:B,2,0)*1000) -> 47.348065
A13: г. Москва | B13: 1990 | F13: Субъект РФ | G13: 8880124 | H13: 69.7 | I13: 1.415 | M13: 100 | AF13: 2256.5 | BX13: =G13/(VLOOKUP(A13,плотность!A:B,2,0)*1000) -> 3415.4323
A14: г. Санкт-Петербург | B14: 1990 | F14: Субъект РФ | G14: 5002444 | H14: 69.7 | I14: 1.395 | M14: 100 | AF14: 1063.6 | BX14: =G14/(VLOOKUP(A14,плотность!A:B,2,0)*1000) -> 3573.1743
A15: г. Севастополь | B15: 1990 | F15: Субъект РФ | BX15: =G15/(VLOOKUP(A15,плотность!A:B,2,0)*1000) -> 0
A16: Дальневосточный федеральный округ | B16: 1990 | F16: Федеральный округ | G16: 8044797 | H16: 67.2 | M16: 76.08 | AF16: 3817.2 | BX16: =G16/(VLOOKUP(A16,плотность!A:B,2,0)*1000) -> #VALUE!
A17: Еврейская автономная область | B17: 1990 | F17: Субъект РФ | G17: 218330 | H17: 66.2 | I17: 2.397 | M17: 65.01 | AF17: 114.8 | BX17: =G17/(VLOOKUP(A17,плотность!A:B,2,0)*1000) -> 6.0146006
A18: Забайкальский край | B18: 1990 | F18: Субъект РФ | G18: 1320562 | H18: 66.8 | I18: 2.484 | M18: 63.86 | AF18: 613.6 | BX18: =G18/(VLOOKUP(A18,плотность!A:B,2,0)*1000) -> 1.6766912
A19: Ивановская область | B19: 1990 | F19: Субъект РФ | G19: 1295215 | H19: 68.8 | I19: 1.72 | M19: 82.3 | AF19: 498.8 | BX19: =G19/(VLOOKUP(A19,плотность!A:B,2,0)*1000) -> 60.524065
A20: Иркутская область | B20: 1990 | F20: Субъект РФ | G20: 2794858 | H20: 66.5 | I20: 2.216 | M20: 80.36 | AF20: 1511.6 | BX20: =G20/(VLOOKUP(A20,плотность!A:B,2,0)*1000) -> 15.719111
A21: Кабардино-Балкарская Республика | B21: 1990 | F21: Субъект РФ | G21: 762288 | H21: 71 | I21: 2.447 | M21: 60.86 | AF21: 200.9 | BX21: =G21/(VLOOKUP(A21,плотность!A:B,2,0)*1000) -> 60.98304
A22: Калининградская область | B22: 1990 | F22: Субъект РФ | G22: 881211 | H22: 68.7 | I22: 1.81 | M22: 78.97 | AF22: 357 | BX22: =G22/(VLOOKUP(A22,плотность!A:B,2,0)*1000) -> 58.358344
A23: Калужская область | B23: 1990 | F23: Субъект РФ | G23: 1068443 | H23: 68.9 | I23: 1.777 | M23: 69.77 | AF23: 580.7 | BX23: =G23/(VLOOKUP(A23,плотность!A:B,2,0)*1000) -> 35.853792
A24: Камчатский край | B24: 1990 | F24: Субъект РФ | G24: 476911 | H24: 65.9 | I24: 1.687 | M24: 81.5 | AF24: 210 | BX24: =G24/(VLOOKUP(A24,плотность!A:B,2,0)*1000) -> 1.3177977
A25: Карачаево-Черкесская Республика | B25: 1990 | F25: Субъект РФ | G25: 419136 | H25: 72.3 | I25: 2.193 | M25: 48.99 | AF25: 290.5 | BX25: =G25/(VLOOKUP(A25,плотность!A:B,2,0)*1000) -> 52.392
A26: Кемеровская область - Кузбасс | B26: 1990 | F26: Субъект РФ (устаревший) | G26: 3099236 | H26: 67.5 | I26: 1.92 | M26: 87.12 | AF26: 1244.7 | BX26: =G26/(VLOOKUP(A26,плотность!A:B,2,0)*1000) -> 32.384911
A27: Кировская область | B27: 1990 | F27: Субъект РФ | G27: 1651726 | H27: 69.5 | I27: 2.008 | M27: 69.35 | AF27: 859.1 | BX27: =G27/(VLOOKUP(A27,плотность!A:B,2,0)*1000) -> 13.352676
A28: Коми-Пермяцкий округ, входящий в состав Пермского края | B28: 1990 | F28: Субъект РФ (устаревший) | G28: 145576 | M28: 30.36 | AF28: 76 | BX28: =G28/(VLOOKUP(A28,плотность!A:B,2,0)*1000) -> 4.4382927
A29: Корякский округ, входящий в состав Камчатского края | B29: 1990 | F29: Субъект РФ (устаревший) | G29: 37622 | M29: 37.7 | AF29: 30 | BX29: =G29/(VLOOKUP(A29,плотность!A:B,2,0)*1000) -> 0.12857826
A30: Костромская область | B30: 1990 | F30: Субъект РФ | G30: 804999 | H30: 68.7 | I30: 1.926 | M30: 68.85 | AF30: 362.6 | BX30: =G30/(VLOOKUP(A30,плотность!A:B,2,0)*1000) -> 13.372076
A31: Краснодарский край | B31: 1990 | F31: Субъект РФ | G31: 4638102 | H31: 68.7 | I31: 2.059 | M31: 54.25 | AF31: 1495.9 | BX31: =G31/(VLOOKUP(A31,плотность!A:B,2,0)*1000) -> 61.431815
A32: Красноярский край | B32: 1990 | F32: Субъект РФ | G32: 3155929 | H32: 67.9 | I32: 1.882 | M32: 73.94 | AF32: 1741.9 | BX32: =G32/(VLOOKUP(A32,плотность!A:B,2,0)*1000) -> 32.977315
A33: Крымский федеральный округ | B33: 1990 | F33: Федеральный округ | BX33: =G33/(VLOOKUP(A33,плотность!A:B,2,0)*1000) -> 0
A34: Курганская область | B34: 1990 | F34: Субъект РФ | G34: 1107280 | H34: 69.2 | I34: 2.148 | M34: 54.77 | AF34: 551.6 | BX34: =G34/(VLOOKUP(A34,плотность!A:B,2,0)*1000) -> 0.75623549
A35: Курская область | B35: 1990 | F35: Субъект РФ | G35: 1332957 | H35: 69 | I35: 1.848 | M35: 58.4 | AF35: 449.9 | BX35: =G35/(VLOOKUP(A35,плотность!A:B,2,0)*1000) -> 44.4319
A36: Ленинградская область | B36: 1990 | F36: Субъект РФ | G36: 1667280 | H36: 68.3 | I36: 1.663 | M36: 66.05 | AF36: 808.1 | BX36: =G36/(VLOOKUP(A36,плотность!A:B,2,0)*1000) -> 19.872229
A37: Липецкая область | B37: 1990 | F37: Субъект РФ | G37: 1231486 | H37: 70 | I37: 1.807 | M37: 62.64 | AF37: 575 | BX37: =G37/(VLOOKUP(A37,плотность!A:B,2,0)*1000) -> 51.311917
A38: Магаданская область | B38: 1990 | F38: Субъект РФ | G38: 390276 | H38: 66.2 | I38: 1.894 | M38: 84.29 | AF38: 194.5 | BX38: =G38/(VLOOKUP(A38,плотность!A:B,2,0)*1000) -> 0.54092308
A39: Места традиционного проживания и традиционной хозяйственной деятельности коренных малочисленных народов Севера, Сибири и Дальнего Востока Российской Федерации | B39: 1990 | F39: Места | BX39: =G39/(VLOOKUP(A39,плотность!A:B,2,0)*1000) -> #N/A
A40: Московская область | B40: 1990 | F40: Субъект РФ | G40: 6700180 | H40: 69.6 | I40: 1.44 | M40: 79.67 | AF40: 2379.9 | BX40: =G40/(VLOOKUP(A40,плотность!A:B,2,0)*1000) -> 151.2456
...

Sheet плотность
B1: Площадь территории, тыс. км2
A2: Российская Федерация | B2: 17125.2
A3: Центральный федеральный округ | B3: 650.2
A4: Белгородская область | B4: 27.1
A5: Брянская область | B5: 34.9
A6: Владимирская область | B6: 29.1
A7: Воронежская область | B7: 52.2
A8: Ивановская область | B8: 21.4
A9: Калужская область | B9: 29.8
A10: Костромская область | B10: 60.2
A11: Курская область | B11: 30
A12: Липецкая область | B12: 24
A13: Московская область | B13: 44.3
... A51: Чеченская Республика | B51: 66.2
A52: Ставропольский край | B52: 1037.0
A53: Приволжский федеральный округ | B53: 142.9
A54: Республика Башкортостан | B54: 23.4
A55: Republic of Bashkortostan | B55: 26.1
A56: Республика Марий Эл | B56: 67.8
A57: Республика Мордовия | B57: 42.1
A58: Республика Татарстан (Татарстан) | B58: 18.3
A59: Удмуртская Республика | B59: 160.2
A60: Чувашская Республика – Чувашия | B60: 120.4
A61: Пермский край | B61: 76.6
A62: Кировская область | B62: 123.7
A63: Нижегородская область | B63: 43.4
A64: Оренбургская область | B64: 53.6
... A74: Территория Ямало-Ненецкого автономного округа | B74: 88.6
A75: Тюменская область без автономных округов | B75: 4361.7
A76: Челябинская область | B76: 92.9
A77: Сибирский федеральный округ | B77: 168.6
A78: Республика Алтай | B78: 61.6
A79: Республика Тыва | B79: 168
A80: Республика Хакасия | B80: 2366.8
A81: Алтайский край | B81: 774.8
A82: Красноярский край | B82: 95.7
A83: Иркутская область | B83: 177.8
A84: Кемеровская область | B84: 141.1
A85: Новосибирская область | B85: 314.4
A86: Омская область | B86: 6952.6
...
